<?xml version="1.0" ?>
<!-- =================================================================================== -->
<!-- |    This document was autogenerated by xacro from src/reachy_description/urdf/reachy.urdf.xacro | -->
<!-- |    EDITING THIS FILE BY HAND IS NOT RECOMMENDED                                 | -->
<!-- =================================================================================== -->
<robot name="reachy_2023">
  <!-- convergence angle (rad) of the cameras. 0=parallel-->
  <link name="world"/>
  <joint name="world_joint" type="fixed">
    <origin rpy="0 0 0" xyz="0 0 1.0"/>
    <parent link="world"/>
    <child link="torso"/>
  </joint>
  <link name="torso">
    <inertial>
      <origin rpy="0.0 0.0 0.0" xyz="0.0 0.019 -0.009"/>
      <mass value="0.527"/>
      <inertia ixx="2.89598e-3" ixy="-1.16791e-6" ixz="-8.28749e-6" iyy="4.491e-3" iyz="2.343e-4" izz="3.995e-3"/>
    </inertial>
    <visual name="">
      <origin rpy="0.0 0.0 0.0" xyz="0.0 0.0 0.0"/>
      <geometry>
        <mesh filename="file:///home/hpm-mv/Documents/Building-Humanoids/Software/ros2_ws/install/reachy_description/share/reachy_description/meshes/torso.dae"/>
      </geometry>
    </visual>
    <collision>
      <origin rpy="0 0.05 0" xyz="0 0 -0.1"/>
      <geometry>
        <box size="0.11 0.2 0.32"/>
      </geometry>
    </collision>
  </link>
  <gazebo reference="torso">
    <material>Gazebo/White</material>
    <static>true</static>
  </gazebo>
  <link name="r_shoulder">
    <inertial>
      <origin rpy="1.57 1.57 0.0" xyz="-0.016 0.036 0.0"/>
      <mass value="0.053"/>
      <inertia ixx="3.308e-4" ixy="9.972e-8" ixz="-2.037e-9" iyy="4.650e-5" iyz="2.113e-6" izz="3.545e-5"/>
    </inertial>
    <visual name="">
      <origin rpy="1.57 1.57 0.0" xyz="0.0 0.04 0.0"/>
      <geometry>
        <mesh filename="file:///home/hpm-mv/Documents/Building-Humanoids/Software/ros2_ws/install/reachy_description/share/reachy_description/meshes/shoulder.dae"/>
      </geometry>
    </visual>
    <collision>
      <origin rpy="1.57 1.57 0.0" xyz="0.0 0.04 0.0"/>
      <geometry>
        <cylinder length="0.09" radius="0.035"/>
      </geometry>
    </collision>
  </link>
  <joint name="r_shoulder_pitch" type="revolute">
    <origin rpy="0.0 0.0 0.0" xyz="0.0 -0.19 0.0"/>
    <parent link="torso"/>
    <child link="r_shoulder"/>
    <axis xyz="0 1 0"/>
    <limit effort="10." lower="-2.618" upper="1.57" velocity="0.0"/>
    <dynamics damping="0.1" friction="0.1"/>
  </joint>
  <link name="r_shoulder_x">
    <inertial>
      <origin rpy="0.0 0.0 0.0" xyz="-0.0 0.0 -0.019"/>
      <mass value="0.158"/>
      <inertia ixx="6.887e+4" ixy="5.393e+0" ixz="-9.155e+2" iyy="7.895e+4" iyz="4.512e-1" izz="4.235e+4"/>
    </inertial>
    <visual name="">
      <origin rpy="0.0 0.0 0.0" xyz="0.0 0.0 0.0"/>
      <geometry>
        <mesh filename="file:///home/hpm-mv/Documents/Building-Humanoids/Software/ros2_ws/install/reachy_description/share/reachy_description/meshes/shoulder_x.dae"/>
      </geometry>
    </visual>
    <collision>
      <origin rpy="0.0 0.0 0.0" xyz="0 0 -0.02"/>
      <geometry>
        <cylinder length="0.04" radius="0.035"/>
      </geometry>
    </collision>
  </link>
  <joint name="r_shoulder_roll" type="revolute">
    <origin rpy="0.0 0.0 0.0" xyz="0 0 0"/>
    <parent link="r_shoulder"/>
    <child link="r_shoulder_x"/>
    <axis xyz="1 0 0"/>
    <limit effort="10." lower="-3.14" upper="0.174" velocity="0.0"/>
    <dynamics damping="0.1" friction="0.1"/>
  </joint>
  <link name="r_upper_arm">
    <inertial>
      <origin rpy="0.0 0.0 0.0" xyz="-0.004 0.0 -0.1426"/>
      <mass value="0.430"/>
      <inertia ixx="3.264e-3" ixy="-4.027e-8" ixz="1.395e-4" iyy="3.345e-3" iyz="1.885e-6" izz="2.616e-4"/>
    </inertial>
    <visual name="">
      <origin rpy="0.0 0.0 0.0" xyz="0.0 0.0 -0.0526"/>
      <geometry>
        <mesh filename="file:///home/hpm-mv/Documents/Building-Humanoids/Software/ros2_ws/install/reachy_description/share/reachy_description/meshes/upper_arm.dae"/>
      </geometry>
    </visual>
    <collision>
      <origin rpy="0.0 0.0 0.0" xyz="0.0 0.0 -0.16"/>
      <geometry>
        <cylinder length="0.25" radius="0.04"/>
      </geometry>
    </collision>
  </link>
  <joint name="r_arm_yaw" type="revolute">
    <origin rpy="0.0 0.0 0.0" xyz="0 0 0"/>
    <parent link="r_shoulder_x"/>
    <child link="r_upper_arm"/>
    <axis xyz="0 0 1"/>
    <limit effort="10." lower="-1.57" upper="1.57" velocity="0.0"/>
    <dynamics damping="0.1" friction="0.1"/>
  </joint>
  <link name="r_forearm">
    <inertial>
      <origin rpy="0.0 0.0 0.0" xyz="-0.008 0.0 -0.058"/>
      <mass value="0.162"/>
      <inertia ixx="2.532e-4" ixy="-2.999e-8" ixz="1.448e-5" iyy="2.538e-4" iyz="-4.323e-8" izz="1.234e-4"/>
    </inertial>
    <visual name="">
      <origin rpy="0.0 0.0 0.0" xyz="0.0 0.0 0.0"/>
      <geometry>
        <mesh filename="file:///home/hpm-mv/Documents/Building-Humanoids/Software/ros2_ws/install/reachy_description/share/reachy_description/meshes/forearm.dae"/>
      </geometry>
    </visual>
    <collision>
      <origin rpy="0.0 0.0 0.0" xyz="0.0 0.0 -0.058"/>
      <geometry>
        <cylinder length="0.09" radius="0.04"/>
      </geometry>
    </collision>
  </link>
  <joint name="r_elbow_pitch" type="revolute">
    <origin rpy="0.0 0.0 0.0" xyz="0 0 -0.28"/>
    <parent link="r_upper_arm"/>
    <child link="r_forearm"/>
    <axis xyz="0 1 0"/>
    <limit effort="10." lower="-2.182" upper="0" velocity="0.0"/>
    <dynamics damping="0.1" friction="0.1"/>
  </joint>
  <link name="r_wrist">
    <inertial>
      <origin rpy="0.0 0.0 0.0" xyz="0.0 0.0 -0.193"/>
      <mass value="0.197"/>
      <inertia ixx="6.157e-4" ixy="5.706e-8" ixz="-1.045e-5" iyy="6.280e-4" iyz="4.862e-7" izz="1.050e-4"/>
    </inertial>
    <visual name="">
      <origin rpy="0.0 0.0 0.0" xyz="0.0 0.0 -0.100"/>
      <geometry>
        <mesh filename="file:///home/hpm-mv/Documents/Building-Humanoids/Software/ros2_ws/install/reachy_description/share/reachy_description/meshes/wrist.dae"/>
      </geometry>
    </visual>
    <collision>
      <origin rpy="0.0 0.0 0.0" xyz="0.0 0.0 -0.18"/>
      <geometry>
        <cylinder length="0.14" radius="0.035"/>
      </geometry>
    </collision>
  </link>
  <joint name="r_forearm_yaw" type="revolute">
    <origin rpy="0.0 0.0 0.0" xyz="0 0 0"/>
    <parent link="r_forearm"/>
    <child link="r_wrist"/>
    <axis xyz="0 0 1"/>
    <limit effort="10." lower="-1.745" upper="1.745" velocity="0.0"/>
    <dynamics damping="0.1" friction="0.1"/>
  </joint>
  <link name="r_wrist2hand">
    <inertial>
      <origin rpy="0.0 0.0 0.0" xyz="0.0 0.0 0.014"/>
      <mass value="0.01"/>
      <inertia ixx="6.750e-6" ixy="3.732e-11" ixz="-1.581e-11" iyy="6.060e-6" iyz="-1.746e-12" izz="5.774e-6"/>
    </inertial>
    <visual name="">
      <origin rpy="0.0 0.0 0.0" xyz="0.0 0.0 0.0"/>
      <geometry>
        <mesh filename="file:///home/hpm-mv/Documents/Building-Humanoids/Software/ros2_ws/install/reachy_description/share/reachy_description/meshes/wrist2hand.dae"/>
      </geometry>
    </visual>
    <collision>
      <origin rpy="0.0 0.0 0.0" xyz="0.0 0.0 -0.03"/>
      <geometry>
        <cylinder length="0.06" radius="0.03"/>
      </geometry>
    </collision>
  </link>
  <joint name="r_wrist_pitch" type="revolute">
    <origin rpy="0.0 0.0 0.0" xyz="0 0 -0.25"/>
    <parent link="r_wrist"/>
    <child link="r_wrist2hand"/>
    <axis xyz="0 1 0"/>
    <limit effort="10." lower="-0.785" upper="0.785" velocity="0.0"/>
    <dynamics damping="0.1" friction="0.1"/>
  </joint>
  <link name="r_gripper_thumb">
    <inertial>
      <origin rpy="0.0 1.57 0.0" xyz="0.032 -0.008 0.0"/>
      <mass value="0.173"/>
      <inertia ixx="1.083e-4" ixy="-3.476e-5" ixz="1.331e-6" iyy="1.421e-4" iyz="6.730e-7" izz="2.112e-4"/>
    </inertial>
    <visual name="">
      <origin rpy="0.0 1.57 0.0" xyz="0.0 0.0 0.0"/>
      <geometry>
        <mesh filename="file:///home/hpm-mv/Documents/Building-Humanoids/Software/ros2_ws/install/reachy_description/share/reachy_description/meshes/r_gripper_thumb.dae"/>
      </geometry>
    </visual>
    <collision>
      <origin rpy="0.0 1.57 0.0" xyz="0.0 0.0 0.0"/>
      <geometry>
        <mesh filename="file:///home/hpm-mv/Documents/Building-Humanoids/Software/ros2_ws/install/reachy_description/share/reachy_description/meshes/r_gripper_thumb.dae"/>
      </geometry>
      <!-- <origin xyz="0.0 0.02 -0.06" rpy="0.0 1.57 0.0"/> -->
      <!-- <geometry> -->
      <!--     <box size="0.1 0.012 0.035" /> -->
      <!-- </geometry> -->
    </collision>
  </link>
  <gazebo reference="r_gripper_thumb">
    <self_collide>1</self_collide>
  </gazebo>
  <joint name="r_wrist_roll" type="revolute">
    <origin rpy="0.0 0.0 0.0" xyz="0 0 -0.0325"/>
    <parent link="r_wrist2hand"/>
    <child link="r_gripper_thumb"/>
    <axis xyz="1 0 0"/>
    <limit effort="10." lower="-0.785" upper="0.785" velocity="0.0"/>
    <dynamics damping="0.1" friction="0.1"/>
  </joint>
  <link name="r_gripper_finger">
    <inertial>
      <origin rpy="0.0 1.57 0.0" xyz="-0.005 -0.043 -0.0"/>
      <mass value="0.035"/>
      <inertia ixx="9.166e-5" ixy="-6.559e-6" ixz="-3.952e-8" iyy="1.062e-5" iyz="5.276e-9" izz="8.704e-5"/>
    </inertial>
    <visual name="">
      <origin rpy="0.0 1.57 0.0" xyz="0.0 0.0 0.0"/>
      <geometry>
        <mesh filename="file:///home/hpm-mv/Documents/Building-Humanoids/Software/ros2_ws/install/reachy_description/share/reachy_description/meshes/r_gripper_finger.dae"/>
      </geometry>
    </visual>
    <collision>
      <origin rpy="0.0 1.57 0.0" xyz="0.0 0.0 0.0"/>
      <geometry>
        <mesh filename="file:///home/hpm-mv/Documents/Building-Humanoids/Software/ros2_ws/install/reachy_description/share/reachy_description/meshes/r_gripper_finger.dae"/>
      </geometry>
      <!-- <origin xyz="0.0 ${-0.01*reflect} -0.02" rpy="0.0 1.57 0.0"/> -->
      <!-- <geometry> -->
      <!--     <box size="0.1 0.012 0.035" /> -->
      <!-- </geometry> -->
    </collision>
  </link>
  <gazebo reference="r_gripper_finger">
    <self_collide>1</self_collide>
  </gazebo>
  <link name="r_arm_tip">
    <inertial>
      <origin rpy="0.0 0.0 0.0" xyz="0.0 0.0 0.0"/>
      <mass value="0.001"/>
      <inertia ixx="1.0e-6" ixy="1.0e-8" ixz="1.0e-8" iyy="1.0e-6" iyz="1.0e-8" izz="1.0e-6"/>
    </inertial>
  </link>
  <joint name="r_arm_tip" type="fixed">
    <origin rpy="0 0 0" xyz="0 -0.012 -0.085"/>
    <parent link="r_gripper_thumb"/>
    <child link="r_arm_tip"/>
  </joint>
  <joint name="r_gripper" type="revolute">
    <origin rpy="0.0 0.0 0.0" xyz="0.0 -0.037 -0.03998"/>
    <parent link="r_gripper_thumb"/>
    <child link="r_gripper_finger"/>
    <axis xyz="1 0 0"/>
    <limit effort="10." lower="-1.2" upper="0.35" velocity="0.0"/>
    <dynamics damping="0.1" friction="0.1"/>
  </joint>
  <!-- Doesn't work... -->
  <!-- <xacro:if value="$(arg use_gazebo)"> -->
  <!--   <gazebo reference="${prefix}_gripper_thumb"> -->
  <!--     <provideFeedback>true</provideFeedback> -->
  <!--   </gazebo> -->
  <!--   <gazebo> -->
  <!--     <plugin name="gazebo_ros_force_sensor" filename="libgazebo_ros_force.so"> -->
  <!--       <ros> -->
  <!--         <!-\- Add namespace and remap the default topic -\-> -->
  <!--         <namespace>/${prefix}_force_sensor</namespace> -->
  <!--       </ros> -->
  <!--       <link_name>${prefix}_gripper_thumb</link_name> -->
  <!--       <force_frame>world</force_frame> -->
  <!--       <update_rate>200</update_rate> -->
  <!--       <update_rate>1</update_rate> -->
  <!--       <gaussian_noise>0.01</gaussian_noise> -->
  <!--     </plugin> -->
  <!--   </gazebo> -->
  <!-- </xacro:if> -->
  <!-- <ros2_control name="r_arm" type="system">
    <hardware>
      <plugin>mock_components/GenericSystem</plugin>
    </hardware>
    <joint name="r_shoulder_pitch">
      <state_interface name="position">
        <param name="initial_value">0.0</param>
      </state_interface>
      <state_interface name="velocity">
        <param name="initial_value">0.0</param>
      </state_interface>
      <state_interface name="effort">
        <param name="initial_value">0.0</param>
      </state_interface>
      <state_interface name="temperature">
        <param name="initial_value">0.0</param>
      </state_interface>
      <state_interface name="torque">
        <param name="initial_value">0.0</param>
      </state_interface>
      <command_interface name="position"/>
      <command_interface name="torque"/>
      <command_interface name="speed_limit"/>
      <state_interface name="speed_limit"/>
      <command_interface name="torque_limit"/>
      <state_interface name="torque_limit"/>
      <state_interface name="p_gain"/>
      <command_interface name="p_gain"/>
      <state_interface name="i_gain"/>
      <command_interface name="i_gain"/>
      <state_interface name="d_gain"/>
      <command_interface name="d_gain"/>
    </joint>
    <joint name="r_shoulder_roll">
      <state_interface name="position">
        <param name="initial_value">0.0</param>
      </state_interface>
      <state_interface name="velocity">
        <param name="initial_value">0.0</param>
      </state_interface>
      <state_interface name="effort">
        <param name="initial_value">0.0</param>
      </state_interface>
      <state_interface name="temperature">
        <param name="initial_value">0.0</param>
      </state_interface>
      <state_interface name="torque">
        <param name="initial_value">0.0</param>
      </state_interface>
      <command_interface name="position"/>
      <command_interface name="torque"/>
      <command_interface name="speed_limit"/>
      <state_interface name="speed_limit"/>
      <command_interface name="torque_limit"/>
      <state_interface name="torque_limit"/>
      <state_interface name="p_gain"/>
      <command_interface name="p_gain"/>
      <state_interface name="i_gain"/>
      <command_interface name="i_gain"/>
      <state_interface name="d_gain"/>
      <command_interface name="d_gain"/>
    </joint>
    <joint name="r_arm_yaw">
      <state_interface name="position">
        <param name="initial_value">0.0</param>
      </state_interface>
      <state_interface name="velocity">
        <param name="initial_value">0.0</param>
      </state_interface>
      <state_interface name="effort">
        <param name="initial_value">0.0</param>
      </state_interface>
      <state_interface name="temperature">
        <param name="initial_value">0.0</param>
      </state_interface>
      <state_interface name="torque">
        <param name="initial_value">0.0</param>
      </state_interface>
      <command_interface name="position"/>
      <command_interface name="torque"/>
      <command_interface name="speed_limit"/>
      <state_interface name="speed_limit"/>
      <command_interface name="torque_limit"/>
      <state_interface name="torque_limit"/>
      <state_interface name="p_gain"/>
      <command_interface name="p_gain"/>
      <state_interface name="i_gain"/>
      <command_interface name="i_gain"/>
      <state_interface name="d_gain"/>
      <command_interface name="d_gain"/>
    </joint>
    <joint name="r_elbow_pitch">
      <state_interface name="position">
        <param name="initial_value">0.0</param>
      </state_interface>
      <state_interface name="velocity">
        <param name="initial_value">0.0</param>
      </state_interface>
      <state_interface name="effort">
        <param name="initial_value">0.0</param>
      </state_interface>
      <state_interface name="temperature">
        <param name="initial_value">0.0</param>
      </state_interface>
      <state_interface name="torque">
        <param name="initial_value">0.0</param>
      </state_interface>
      <command_interface name="position"/>
      <command_interface name="torque"/>
      <command_interface name="speed_limit"/>
      <state_interface name="speed_limit"/>
      <command_interface name="torque_limit"/>
      <state_interface name="torque_limit"/>
      <state_interface name="p_gain"/>
      <command_interface name="p_gain"/>
      <state_interface name="i_gain"/>
      <command_interface name="i_gain"/>
      <state_interface name="d_gain"/>
      <command_interface name="d_gain"/>
    </joint>
    <joint name="r_forearm_yaw">
      <state_interface name="position">
        <param name="initial_value">0.0</param>
      </state_interface>
      <state_interface name="velocity">
        <param name="initial_value">0.0</param>
      </state_interface>
      <state_interface name="effort">
        <param name="initial_value">0.0</param>
      </state_interface>
      <state_interface name="temperature">
        <param name="initial_value">0.0</param>
      </state_interface>
      <state_interface name="torque">
        <param name="initial_value">0.0</param>
      </state_interface>
      <command_interface name="position"/>
      <command_interface name="torque"/>
      <command_interface name="speed_limit"/>
      <state_interface name="speed_limit"/>
      <command_interface name="torque_limit"/>
      <state_interface name="torque_limit"/>
      <state_interface name="p_gain"/>
      <command_interface name="p_gain"/>
      <state_interface name="i_gain"/>
      <command_interface name="i_gain"/>
      <state_interface name="d_gain"/>
      <command_interface name="d_gain"/>
    </joint>
    <joint name="r_wrist_pitch">
      <state_interface name="position">
        <param name="initial_value">0.0</param>
      </state_interface>
      <state_interface name="velocity">
        <param name="initial_value">0.0</param>
      </state_interface>
      <state_interface name="effort">
        <param name="initial_value">0.0</param>
      </state_interface>
      <state_interface name="temperature">
        <param name="initial_value">0.0</param>
      </state_interface>
      <state_interface name="torque">
        <param name="initial_value">0.0</param>
      </state_interface>
      <command_interface name="position"/>
      <command_interface name="torque"/>
      <command_interface name="speed_limit"/>
      <state_interface name="speed_limit"/>
      <command_interface name="torque_limit"/>
      <state_interface name="torque_limit"/>
      <state_interface name="p_gain"/>
      <command_interface name="p_gain"/>
      <state_interface name="i_gain"/>
      <command_interface name="i_gain"/>
      <state_interface name="d_gain"/>
      <command_interface name="d_gain"/>
    </joint>
    <joint name="r_wrist_roll">
      <state_interface name="position">
        <param name="initial_value">0.0</param>
      </state_interface>
      <state_interface name="velocity">
        <param name="initial_value">0.0</param>
      </state_interface>
      <state_interface name="effort">
        <param name="initial_value">0.0</param>
      </state_interface>
      <state_interface name="temperature">
        <param name="initial_value">0.0</param>
      </state_interface>
      <state_interface name="torque">
        <param name="initial_value">0.0</param>
      </state_interface>
      <command_interface name="position"/>
      <command_interface name="torque"/>
      <command_interface name="speed_limit"/>
      <state_interface name="speed_limit"/>
      <command_interface name="torque_limit"/>
      <state_interface name="torque_limit"/>
      <state_interface name="p_gain"/>
      <command_interface name="p_gain"/>
      <state_interface name="i_gain"/>
      <command_interface name="i_gain"/>
      <state_interface name="d_gain"/>
      <command_interface name="d_gain"/>
    </joint>
    <joint name="r_gripper">
      <state_interface name="position">
        <param name="initial_value">0.0</param>
      </state_interface>
      <state_interface name="velocity">
        <param name="initial_value">0.0</param>
      </state_interface>
      <state_interface name="effort">
        <param name="initial_value">0.0</param>
      </state_interface>
      <state_interface name="temperature">
        <param name="initial_value">0.0</param>
      </state_interface>
      <state_interface name="torque">
        <param name="initial_value">0.0</param>
      </state_interface>
      <command_interface name="position"/>
      <command_interface name="torque"/>
      <command_interface name="speed_limit"/>
      <state_interface name="speed_limit"/>
      <command_interface name="torque_limit"/>
      <state_interface name="torque_limit"/>
      <state_interface name="p_gain"/>
      <command_interface name="p_gain"/>
      <state_interface name="i_gain"/>
      <command_interface name="i_gain"/>
      <state_interface name="d_gain"/>
      <command_interface name="d_gain"/>
    </joint>
    <sensor name="r_force_gripper">
      <state_interface name="force">
        <param name="initial_value">0.0</param>
      </state_interface>
    </sensor>
    <joint name="r_shoulder_fan">
      <state_interface name="state">
        <param name="initial_value">0.0</param>
      </state_interface>
      <command_interface name="state"/>
    </joint>
    <joint name="r_elbow_fan">
      <state_interface name="state">
        <param name="initial_value">0.0</param>
      </state_interface>
      <command_interface name="state"/>
    </joint>
    <joint name="r_wrist_fan">
      <state_interface name="state">
        <param name="initial_value">0.0</param>
      </state_interface>
      <command_interface name="state"/>
    </joint>
  </ros2_control> -->
  <link name="l_shoulder">
    <inertial>
      <origin rpy="-1.57 1.57 0.0" xyz="-0.016 0.044 0.0"/>
      <mass value="0.053"/>
      <inertia ixx="3.308e-4" ixy="9.972e-8" ixz="-2.037e-9" iyy="4.650e-5" iyz="2.113e-6" izz="3.545e-5"/>
    </inertial>
    <visual name="">
      <origin rpy="-1.57 1.57 0.0" xyz="0.0 -0.04 0.0"/>
      <geometry>
        <mesh filename="file:///home/hpm-mv/Documents/Building-Humanoids/Software/ros2_ws/install/reachy_description/share/reachy_description/meshes/shoulder.dae"/>
      </geometry>
    </visual>
    <collision>
      <origin rpy="-1.57 1.57 0.0" xyz="0.0 -0.04 0.0"/>
      <geometry>
        <cylinder length="0.09" radius="0.035"/>
      </geometry>
    </collision>
  </link>
  <joint name="l_shoulder_pitch" type="revolute">
    <origin rpy="0.0 0.0 0.0" xyz="0.0 0.19 0.0"/>
    <parent link="torso"/>
    <child link="l_shoulder"/>
    <axis xyz="0 1 0"/>
    <limit effort="10." lower="-2.618" upper="1.57" velocity="0.0"/>
    <dynamics damping="0.1" friction="0.1"/>
  </joint>
  <link name="l_shoulder_x">
    <inertial>
      <origin rpy="0.0 0.0 0.0" xyz="-0.0 0.0 -0.019"/>
      <mass value="0.158"/>
      <inertia ixx="6.887e+4" ixy="5.393e+0" ixz="-9.155e+2" iyy="7.895e+4" iyz="4.512e-1" izz="4.235e+4"/>
    </inertial>
    <visual name="">
      <origin rpy="0.0 0.0 0.0" xyz="0.0 0.0 0.0"/>
      <geometry>
        <mesh filename="file:///home/hpm-mv/Documents/Building-Humanoids/Software/ros2_ws/install/reachy_description/share/reachy_description/meshes/shoulder_x.dae"/>
      </geometry>
    </visual>
    <collision>
      <origin rpy="0.0 0.0 0.0" xyz="0 0 -0.02"/>
      <geometry>
        <cylinder length="0.04" radius="0.035"/>
      </geometry>
    </collision>
  </link>
  <joint name="l_shoulder_roll" type="revolute">
    <origin rpy="0.0 0.0 0.0" xyz="0 0 0"/>
    <parent link="l_shoulder"/>
    <child link="l_shoulder_x"/>
    <axis xyz="1 0 0"/>
    <limit effort="10." lower="-0.174" upper="3.14" velocity="0.0"/>
    <dynamics damping="0.1" friction="0.1"/>
  </joint>
  <link name="l_upper_arm">
    <inertial>
      <origin rpy="0.0 0.0 0.0" xyz="-0.004 0.0 -0.1426"/>
      <mass value="0.430"/>
      <inertia ixx="3.264e-3" ixy="-4.027e-8" ixz="1.395e-4" iyy="3.345e-3" iyz="1.885e-6" izz="2.616e-4"/>
    </inertial>
    <visual name="">
      <origin rpy="0.0 0.0 0.0" xyz="0.0 0.0 -0.0526"/>
      <geometry>
        <mesh filename="file:///home/hpm-mv/Documents/Building-Humanoids/Software/ros2_ws/install/reachy_description/share/reachy_description/meshes/upper_arm.dae"/>
      </geometry>
    </visual>
    <collision>
      <origin rpy="0.0 0.0 0.0" xyz="0.0 0.0 -0.16"/>
      <geometry>
        <cylinder length="0.25" radius="0.04"/>
      </geometry>
    </collision>
  </link>
  <joint name="l_arm_yaw" type="revolute">
    <origin rpy="0.0 0.0 0.0" xyz="0 0 0"/>
    <parent link="l_shoulder_x"/>
    <child link="l_upper_arm"/>
    <axis xyz="0 0 1"/>
    <limit effort="10." lower="-1.57" upper="1.57" velocity="0.0"/>
    <dynamics damping="0.1" friction="0.1"/>
  </joint>
  <link name="l_forearm">
    <inertial>
      <origin rpy="0.0 0.0 0.0" xyz="-0.008 0.0 -0.058"/>
      <mass value="0.162"/>
      <inertia ixx="2.532e-4" ixy="-2.999e-8" ixz="1.448e-5" iyy="2.538e-4" iyz="-4.323e-8" izz="1.234e-4"/>
    </inertial>
    <visual name="">
      <origin rpy="0.0 0.0 0.0" xyz="0.0 0.0 0.0"/>
      <geometry>
        <mesh filename="file:///home/hpm-mv/Documents/Building-Humanoids/Software/ros2_ws/install/reachy_description/share/reachy_description/meshes/forearm.dae"/>
      </geometry>
    </visual>
    <collision>
      <origin rpy="0.0 0.0 0.0" xyz="0.0 0.0 -0.058"/>
      <geometry>
        <cylinder length="0.09" radius="0.04"/>
      </geometry>
    </collision>
  </link>
  <joint name="l_elbow_pitch" type="revolute">
    <origin rpy="0.0 0.0 0.0" xyz="0 0 -0.28"/>
    <parent link="l_upper_arm"/>
    <child link="l_forearm"/>
    <axis xyz="0 1 0"/>
    <limit effort="10." lower="-2.182" upper="0" velocity="0.0"/>
    <dynamics damping="0.1" friction="0.1"/>
  </joint>
  <link name="l_wrist">
    <inertial>
      <origin rpy="0.0 0.0 0.0" xyz="0.0 0.0 -0.193"/>
      <mass value="0.197"/>
      <inertia ixx="6.157e-4" ixy="5.706e-8" ixz="-1.045e-5" iyy="6.280e-4" iyz="4.862e-7" izz="1.050e-4"/>
    </inertial>
    <visual name="">
      <origin rpy="0.0 0.0 0.0" xyz="0.0 0.0 -0.100"/>
      <geometry>
        <mesh filename="file:///home/hpm-mv/Documents/Building-Humanoids/Software/ros2_ws/install/reachy_description/share/reachy_description/meshes/wrist.dae"/>
      </geometry>
    </visual>
    <collision>
      <origin rpy="0.0 0.0 0.0" xyz="0.0 0.0 -0.18"/>
      <geometry>
        <cylinder length="0.14" radius="0.035"/>
      </geometry>
    </collision>
  </link>
  <joint name="l_forearm_yaw" type="revolute">
    <origin rpy="0.0 0.0 0.0" xyz="0 0 0"/>
    <parent link="l_forearm"/>
    <child link="l_wrist"/>
    <axis xyz="0 0 1"/>
    <limit effort="10." lower="-1.745" upper="1.745" velocity="0.0"/>
    <dynamics damping="0.1" friction="0.1"/>
  </joint>
  <link name="l_wrist2hand">
    <inertial>
      <origin rpy="0.0 0.0 0.0" xyz="0.0 0.0 0.014"/>
      <mass value="0.01"/>
      <inertia ixx="6.750e-6" ixy="3.732e-11" ixz="-1.581e-11" iyy="6.060e-6" iyz="-1.746e-12" izz="5.774e-6"/>
    </inertial>
    <visual name="">
      <origin rpy="0.0 0.0 0.0" xyz="0.0 0.0 0.0"/>
      <geometry>
        <mesh filename="file:///home/hpm-mv/Documents/Building-Humanoids/Software/ros2_ws/install/reachy_description/share/reachy_description/meshes/wrist2hand.dae"/>
      </geometry>
    </visual>
    <collision>
      <origin rpy="0.0 0.0 0.0" xyz="0.0 0.0 -0.03"/>
      <geometry>
        <cylinder length="0.06" radius="0.03"/>
      </geometry>
    </collision>
  </link>
  <joint name="l_wrist_pitch" type="revolute">
    <origin rpy="0.0 0.0 0.0" xyz="0 0 -0.25"/>
    <parent link="l_wrist"/>
    <child link="l_wrist2hand"/>
    <axis xyz="0 1 0"/>
    <limit effort="10." lower="-0.785" upper="0.785" velocity="0.0"/>
    <dynamics damping="0.1" friction="0.1"/>
  </joint>
  <link name="l_gripper_thumb">
    <inertial>
      <origin rpy="0.0 1.57 0.0" xyz="0.032 0.008 0.0"/>
      <mass value="0.173"/>
      <inertia ixx="1.083e-4" ixy="-3.476e-5" ixz="1.331e-6" iyy="1.421e-4" iyz="6.730e-7" izz="2.112e-4"/>
    </inertial>
    <visual name="">
      <origin rpy="0.0 1.57 0.0" xyz="0.0 0.0 0.0"/>
      <geometry>
        <mesh filename="file:///home/hpm-mv/Documents/Building-Humanoids/Software/ros2_ws/install/reachy_description/share/reachy_description/meshes/l_gripper_thumb.dae"/>
      </geometry>
    </visual>
    <collision>
      <origin rpy="0.0 1.57 0.0" xyz="0.0 0.0 0.0"/>
      <geometry>
        <mesh filename="file:///home/hpm-mv/Documents/Building-Humanoids/Software/ros2_ws/install/reachy_description/share/reachy_description/meshes/l_gripper_thumb.dae"/>
      </geometry>
      <!-- <origin xyz="0.0 0.02 -0.06" rpy="0.0 1.57 0.0"/> -->
      <!-- <geometry> -->
      <!--     <box size="0.1 0.012 0.035" /> -->
      <!-- </geometry> -->
    </collision>
  </link>
  <gazebo reference="l_gripper_thumb">
    <self_collide>1</self_collide>
  </gazebo>
  <joint name="l_wrist_roll" type="revolute">
    <origin rpy="0.0 0.0 0.0" xyz="0 0 -0.0325"/>
    <parent link="l_wrist2hand"/>
    <child link="l_gripper_thumb"/>
    <axis xyz="1 0 0"/>
    <limit effort="10." lower="-0.785" upper="0.785" velocity="0.0"/>
    <dynamics damping="0.1" friction="0.1"/>
  </joint>
  <link name="l_gripper_finger">
    <inertial>
      <origin rpy="0.0 1.57 0.0" xyz="0.005 -0.043 -0.0"/>
      <mass value="0.035"/>
      <inertia ixx="9.166e-5" ixy="-6.559e-6" ixz="-3.952e-8" iyy="1.062e-5" iyz="5.276e-9" izz="8.704e-5"/>
    </inertial>
    <visual name="">
      <origin rpy="0.0 1.57 0.0" xyz="0.0 0.0 0.0"/>
      <geometry>
        <mesh filename="file:///home/hpm-mv/Documents/Building-Humanoids/Software/ros2_ws/install/reachy_description/share/reachy_description/meshes/l_gripper_finger.dae"/>
      </geometry>
    </visual>
    <collision>
      <origin rpy="0.0 1.57 0.0" xyz="0.0 0.0 0.0"/>
      <geometry>
        <mesh filename="file:///home/hpm-mv/Documents/Building-Humanoids/Software/ros2_ws/install/reachy_description/share/reachy_description/meshes/l_gripper_finger.dae"/>
      </geometry>
      <!-- <origin xyz="0.0 ${-0.01*reflect} -0.02" rpy="0.0 1.57 0.0"/> -->
      <!-- <geometry> -->
      <!--     <box size="0.1 0.012 0.035" /> -->
      <!-- </geometry> -->
    </collision>
  </link>
  <gazebo reference="l_gripper_finger">
    <self_collide>1</self_collide>
  </gazebo>
  <link name="l_arm_tip">
    <inertial>
      <origin rpy="0.0 0.0 0.0" xyz="0.0 0.0 0.0"/>
      <mass value="0.001"/>
      <inertia ixx="1.0e-6" ixy="1.0e-8" ixz="1.0e-8" iyy="1.0e-6" iyz="1.0e-8" izz="1.0e-6"/>
    </inertial>
  </link>
  <joint name="l_arm_tip" type="fixed">
    <origin rpy="0 0 0" xyz="0 -0.012 -0.085"/>
    <parent link="l_gripper_thumb"/>
    <child link="l_arm_tip"/>
  </joint>
  <joint name="l_gripper" type="revolute">
    <origin rpy="0.0 0.0 0.0" xyz="0.0 0.037 -0.03998"/>
    <parent link="l_gripper_thumb"/>
    <child link="l_gripper_finger"/>
    <axis xyz="1 0 0"/>
    <limit effort="10." lower="-0.35" upper="1.2" velocity="0.0"/>
    <dynamics damping="0.1" friction="0.1"/>
  </joint>
  <!-- Doesn't work... -->
  <!-- <xacro:if value="$(arg use_gazebo)"> -->
  <!--   <gazebo reference="${prefix}_gripper_thumb"> -->
  <!--     <provideFeedback>true</provideFeedback> -->
  <!--   </gazebo> -->
  <!--   <gazebo> -->
  <!--     <plugin name="gazebo_ros_force_sensor" filename="libgazebo_ros_force.so"> -->
  <!--       <ros> -->
  <!--         <!-\- Add namespace and remap the default topic -\-> -->
  <!--         <namespace>/${prefix}_force_sensor</namespace> -->
  <!--       </ros> -->
  <!--       <link_name>${prefix}_gripper_thumb</link_name> -->
  <!--       <force_frame>world</force_frame> -->
  <!--       <update_rate>200</update_rate> -->
  <!--       <update_rate>1</update_rate> -->
  <!--       <gaussian_noise>0.01</gaussian_noise> -->
  <!--     </plugin> -->
  <!--   </gazebo> -->
  <!-- </xacro:if> -->
  <!-- <ros2_control name="l_arm" type="system">
    <hardware>
      <plugin>mock_components/GenericSystem</plugin>
    </hardware>
    <joint name="l_shoulder_pitch">
      <state_interface name="position">
        <param name="initial_value">0.0</param>
      </state_interface>
      <state_interface name="velocity">
        <param name="initial_value">0.0</param>
      </state_interface>
      <state_interface name="effort">
        <param name="initial_value">0.0</param>
      </state_interface>
      <state_interface name="temperature">
        <param name="initial_value">0.0</param>
      </state_interface>
      <state_interface name="torque">
        <param name="initial_value">0.0</param>
      </state_interface>
      <command_interface name="position"/>
      <command_interface name="torque"/>
      <command_interface name="speed_limit"/>
      <state_interface name="speed_limit"/>
      <command_interface name="torque_limit"/>
      <state_interface name="torque_limit"/>
      <state_interface name="p_gain"/>
      <command_interface name="p_gain"/>
      <state_interface name="i_gain"/>
      <command_interface name="i_gain"/>
      <state_interface name="d_gain"/>
      <command_interface name="d_gain"/>
    </joint>
    <joint name="l_shoulder_roll">
      <state_interface name="position">
        <param name="initial_value">0.0</param>
      </state_interface>
      <state_interface name="velocity">
        <param name="initial_value">0.0</param>
      </state_interface>
      <state_interface name="effort">
        <param name="initial_value">0.0</param>
      </state_interface>
      <state_interface name="temperature">
        <param name="initial_value">0.0</param>
      </state_interface>
      <state_interface name="torque">
        <param name="initial_value">0.0</param>
      </state_interface>
      <command_interface name="position"/>
      <command_interface name="torque"/>
      <command_interface name="speed_limit"/>
      <state_interface name="speed_limit"/>
      <command_interface name="torque_limit"/>
      <state_interface name="torque_limit"/>
      <state_interface name="p_gain"/>
      <command_interface name="p_gain"/>
      <state_interface name="i_gain"/>
      <command_interface name="i_gain"/>
      <state_interface name="d_gain"/>
      <command_interface name="d_gain"/>
    </joint>
    <joint name="l_arm_yaw">
      <state_interface name="position">
        <param name="initial_value">0.0</param>
      </state_interface>
      <state_interface name="velocity">
        <param name="initial_value">0.0</param>
      </state_interface>
      <state_interface name="effort">
        <param name="initial_value">0.0</param>
      </state_interface>
      <state_interface name="temperature">
        <param name="initial_value">0.0</param>
      </state_interface>
      <state_interface name="torque">
        <param name="initial_value">0.0</param>
      </state_interface>
      <command_interface name="position"/>
      <command_interface name="torque"/>
      <command_interface name="speed_limit"/>
      <state_interface name="speed_limit"/>
      <command_interface name="torque_limit"/>
      <state_interface name="torque_limit"/>
      <state_interface name="p_gain"/>
      <command_interface name="p_gain"/>
      <state_interface name="i_gain"/>
      <command_interface name="i_gain"/>
      <state_interface name="d_gain"/>
      <command_interface name="d_gain"/>
    </joint>
    <joint name="l_elbow_pitch">
      <state_interface name="position">
        <param name="initial_value">0.0</param>
      </state_interface>
      <state_interface name="velocity">
        <param name="initial_value">0.0</param>
      </state_interface>
      <state_interface name="effort">
        <param name="initial_value">0.0</param>
      </state_interface>
      <state_interface name="temperature">
        <param name="initial_value">0.0</param>
      </state_interface>
      <state_interface name="torque">
        <param name="initial_value">0.0</param>
      </state_interface>
      <command_interface name="position"/>
      <command_interface name="torque"/>
      <command_interface name="speed_limit"/>
      <state_interface name="speed_limit"/>
      <command_interface name="torque_limit"/>
      <state_interface name="torque_limit"/>
      <state_interface name="p_gain"/>
      <command_interface name="p_gain"/>
      <state_interface name="i_gain"/>
      <command_interface name="i_gain"/>
      <state_interface name="d_gain"/>
      <command_interface name="d_gain"/>
    </joint>
    <joint name="l_forearm_yaw">
      <state_interface name="position">
        <param name="initial_value">0.0</param>
      </state_interface>
      <state_interface name="velocity">
        <param name="initial_value">0.0</param>
      </state_interface>
      <state_interface name="effort">
        <param name="initial_value">0.0</param>
      </state_interface>
      <state_interface name="temperature">
        <param name="initial_value">0.0</param>
      </state_interface>
      <state_interface name="torque">
        <param name="initial_value">0.0</param>
      </state_interface>
      <command_interface name="position"/>
      <command_interface name="torque"/>
      <command_interface name="speed_limit"/>
      <state_interface name="speed_limit"/>
      <command_interface name="torque_limit"/>
      <state_interface name="torque_limit"/>
      <state_interface name="p_gain"/>
      <command_interface name="p_gain"/>
      <state_interface name="i_gain"/>
      <command_interface name="i_gain"/>
      <state_interface name="d_gain"/>
      <command_interface name="d_gain"/>
    </joint>
    <joint name="l_wrist_pitch">
      <state_interface name="position">
        <param name="initial_value">0.0</param>
      </state_interface>
      <state_interface name="velocity">
        <param name="initial_value">0.0</param>
      </state_interface>
      <state_interface name="effort">
        <param name="initial_value">0.0</param>
      </state_interface>
      <state_interface name="temperature">
        <param name="initial_value">0.0</param>
      </state_interface>
      <state_interface name="torque">
        <param name="initial_value">0.0</param>
      </state_interface>
      <command_interface name="position"/>
      <command_interface name="torque"/>
      <command_interface name="speed_limit"/>
      <state_interface name="speed_limit"/>
      <command_interface name="torque_limit"/>
      <state_interface name="torque_limit"/>
      <state_interface name="p_gain"/>
      <command_interface name="p_gain"/>
      <state_interface name="i_gain"/>
      <command_interface name="i_gain"/>
      <state_interface name="d_gain"/>
      <command_interface name="d_gain"/>
    </joint>
    <joint name="l_wrist_roll">
      <state_interface name="position">
        <param name="initial_value">0.0</param>
      </state_interface>
      <state_interface name="velocity">
        <param name="initial_value">0.0</param>
      </state_interface>
      <state_interface name="effort">
        <param name="initial_value">0.0</param>
      </state_interface>
      <state_interface name="temperature">
        <param name="initial_value">0.0</param>
      </state_interface>
      <state_interface name="torque">
        <param name="initial_value">0.0</param>
      </state_interface>
      <command_interface name="position"/>
      <command_interface name="torque"/>
      <command_interface name="speed_limit"/>
      <state_interface name="speed_limit"/>
      <command_interface name="torque_limit"/>
      <state_interface name="torque_limit"/>
      <state_interface name="p_gain"/>
      <command_interface name="p_gain"/>
      <state_interface name="i_gain"/>
      <command_interface name="i_gain"/>
      <state_interface name="d_gain"/>
      <command_interface name="d_gain"/>
    </joint>
    <joint name="l_gripper">
      <state_interface name="position">
        <param name="initial_value">0.0</param>
      </state_interface>
      <state_interface name="velocity">
        <param name="initial_value">0.0</param>
      </state_interface>
      <state_interface name="effort">
        <param name="initial_value">0.0</param>
      </state_interface>
      <state_interface name="temperature">
        <param name="initial_value">0.0</param>
      </state_interface>
      <state_interface name="torque">
        <param name="initial_value">0.0</param>
      </state_interface>
      <command_interface name="position"/>
      <command_interface name="torque"/>
      <command_interface name="speed_limit"/>
      <state_interface name="speed_limit"/>
      <command_interface name="torque_limit"/>
      <state_interface name="torque_limit"/>
      <state_interface name="p_gain"/>
      <command_interface name="p_gain"/>
      <state_interface name="i_gain"/>
      <command_interface name="i_gain"/>
      <state_interface name="d_gain"/>
      <command_interface name="d_gain"/>
    </joint>
    <sensor name="l_force_gripper">
      <state_interface name="force">
        <param name="initial_value">0.0</param>
      </state_interface>
    </sensor>
    <joint name="l_shoulder_fan">
      <state_interface name="state">
        <param name="initial_value">0.0</param>
      </state_interface>
      <command_interface name="state"/>
    </joint>
    <joint name="l_elbow_fan">
      <state_interface name="state">
        <param name="initial_value">0.0</param>
      </state_interface>
      <command_interface name="state"/>
    </joint>
    <joint name="l_wrist_fan">
      <state_interface name="state">
        <param name="initial_value">0.0</param>
      </state_interface>
      <command_interface name="state"/>
    </joint>
  </ros2_control> -->
  <joint name="neck_roll" type="revolute">
    <origin rpy="0 0.174 0" xyz="0.015 0.0 0.095"/>
    <parent link="torso"/>
    <child link="head_x"/>
    <axis xyz="1 0 0"/>
    <limit effort="10." lower="-0.8" upper="0.8" velocity="0.0"/>
    <dynamics damping="0.1" friction="0.1"/>
  </joint>
  <link name="head_x">
    <inertial>
      <origin rpy="0.0 0.0 0.0" xyz="0.0 0.0 0.0"/>
      <mass value="0.001"/>
      <inertia ixx="1.0e-6" ixy="1.0e-8" ixz="1.0e-8" iyy="1.0e-6" iyz="1.0e-8" izz="1.0e-6"/>
    </inertial>
  </link>
  <joint name="neck_pitch" type="revolute">
    <origin rpy="0.0 0.0 0.0" xyz="0 0 0"/>
    <parent link="head_x"/>
    <child link="head_y"/>
    <axis xyz="0 1 0"/>
    <limit effort="10." lower="-0.8" upper="1.13" velocity="0.0"/>
    <dynamics damping="0.1" friction="0.1"/>
  </joint>
  <link name="head_y">
    <inertial>
      <origin rpy="0.0 0.0 0.0" xyz="0.0 0.0 0.0"/>
      <mass value="0.001"/>
      <inertia ixx="1.0e-6" ixy="1.0e-8" ixz="1.0e-8" iyy="1.0e-6" iyz="1.0e-8" izz="1.0e-6"/>
    </inertial>
  </link>
  <joint name="neck_yaw" type="revolute">
    <origin rpy="0.0 0.0 0.0" xyz="0 0 0"/>
    <parent link="head_y"/>
    <child link="head_z"/>
    <axis xyz="0 0 1"/>
    <limit effort="10." lower="-2.79" upper="2.79" velocity="0.0"/>
    <dynamics damping="0.1" friction="0.1"/>
  </joint>
  <link name="head_z">
    <inertial>
      <origin rpy="0.0 0.0 0.0" xyz="0.0 0.0 0.0"/>
      <mass value="0.001"/>
      <inertia ixx="1.0e-6" ixy="1.0e-8" ixz="1.0e-8" iyy="1.0e-6" iyz="1.0e-8" izz="1.0e-6"/>
    </inertial>
  </link>
  <joint name="neck_fixed" type="fixed">
    <origin rpy="0.0 0.0 0.0" xyz="0 0 0"/>
    <parent link="head_z"/>
    <child link="head"/>
  </joint>
  <!-- Fixed Orbita Arms Visuals -->
  <joint name="neck_top" type="fixed">
    <origin rpy="0 0.174 0" xyz="0.0067 0.0 0.0478"/>
    <parent link="torso"/>
    <child link="top_neck_arm"/>
  </joint>
  <link name="top_neck_arm">
    <inertial>
      <origin rpy="0.0 0.0 0.0" xyz="0.0 0.0 0.0"/>
      <mass value="0.001"/>
      <inertia ixx="1.0e-6" ixy="1.0e-8" ixz="1.0e-8" iyy="1.0e-6" iyz="1.0e-8" izz="1.0e-6"/>
    </inertial>
    <visual name="">
      <origin rpy="0.0 0.0 0.5236" xyz="0.0 0.0 0.0"/>
      <geometry>
        <mesh filename="file:///home/hpm-mv/Documents/Building-Humanoids/Software/ros2_ws/install/reachy_description/share/reachy_description/meshes/orbita_arm.dae"/>
      </geometry>
    </visual>
    <collision>
      <origin rpy="0.0 0.0 0.0" xyz="0.0 0.0 0.0"/>
      <geometry>
        <cylinder length="0.0" radius="0.0"/>
      </geometry>
    </collision>
  </link>
  <joint name="neck_middle" type="fixed">
    <origin rpy="0 0.174 0" xyz="0.0067 0.0 0.0478"/>
    <parent link="torso"/>
    <child link="middle_neck_arm"/>
  </joint>
  <link name="middle_neck_arm">
    <inertial>
      <origin rpy="0.0 0.0 0.0" xyz="0.0 0.0 0.0"/>
      <mass value="0.001"/>
      <inertia ixx="1.0e-6" ixy="1.0e-8" ixz="1.0e-8" iyy="1.0e-6" iyz="1.0e-8" izz="1.0e-6"/>
    </inertial>
    <visual name="">
      <origin rpy="0.0 0.0 2.618" xyz="0.0 0.0 0.0"/>
      <geometry>
        <mesh filename="file:///home/hpm-mv/Documents/Building-Humanoids/Software/ros2_ws/install/reachy_description/share/reachy_description/meshes/orbita_arm.dae"/>
      </geometry>
    </visual>
    <collision>
      <origin rpy="0.0 0.0 0.0" xyz="0.0 0.0 0.0"/>
      <geometry>
        <cylinder length="0.0" radius="0.0"/>
      </geometry>
    </collision>
  </link>
  <joint name="neck_bottom" type="fixed">
    <origin rpy="0 0.174 0" xyz="0.0067 0.0 0.0478"/>
    <parent link="torso"/>
    <child link="bottom_neck_arm"/>
  </joint>
  <link name="bottom_neck_arm">
    <inertial>
      <origin rpy="0.0 0.0 0.0" xyz="0.0 0.0 0.0"/>
      <mass value="0.001"/>
      <inertia ixx="1.0e-6" ixy="1.0e-8" ixz="1.0e-8" iyy="1.0e-6" iyz="1.0e-8" izz="1.0e-6"/>
    </inertial>
    <visual name="">
      <origin rpy="0.0 0.0 -1.57" xyz="0.0 0.0 0.0"/>
      <geometry>
        <mesh filename="file:///home/hpm-mv/Documents/Building-Humanoids/Software/ros2_ws/install/reachy_description/share/reachy_description/meshes/orbita_arm.dae"/>
      </geometry>
    </visual>
    <collision>
      <origin rpy="0.0 0.0 0.0" xyz="0.0 0.0 0.0"/>
      <geometry>
        <cylinder length="0.0" radius="0.0"/>
      </geometry>
    </collision>
  </link>
  <!-- Head Links -->
  <link name="head">
    <inertial>
      <origin rpy="0.0 0.0 0.0" xyz="-0.009 -0.002 0.059"/>
      <mass value="0.237"/>
      <inertia ixx="1.676e-3" ixy="3.068e-6" ixz="1.2449e-4" iyy="1.368e-3" iyz="3.360e-5" izz="8.425e-4"/>
    </inertial>
    <visual name="">
      <origin rpy="0.0 0.0 0.0" xyz="0.0 0.0 0.0"/>
      <geometry>
        <mesh filename="file:///home/hpm-mv/Documents/Building-Humanoids/Software/ros2_ws/install/reachy_description/share/reachy_description/meshes/head.dae"/>
      </geometry>
    </visual>
    <collision>
      <origin rpy="1.57 0.0 0.0" xyz="-0.009 -0.002 0.059"/>
      <geometry>
        <cylinder length="0.15" radius="0.06"/>
      </geometry>
    </collision>
  </link>
  <link name="head_tip">
    </link>
  <joint name="head_tip_fixed" type="fixed">
    <!-- between the cameras -->
    <origin rpy="0.0 0.0 0" xyz="0.02 0 0.06105"/>
    <!-- Rotation center -->
    <!-- <origin xyz="0.0 0 0.0" rpy="0.0 0.0 0"/> -->
    <parent link="head"/>
    <child link="head_tip"/>
  </joint>
  <link name="l_antenna_link">
    <inertial>
      <origin rpy="0.0 0.0 0.0" xyz="-0.001 0.0 0.008"/>
      <mass value="0.004"/>
      <inertia ixx="1.794e-7" ixy="-1.240e-5" ixz="1.91701e-8" iyy="1.5e-7" iyz="3.169e-6" izz="1.933e-7"/>
    </inertial>
    <visual name="">
      <origin rpy="0.0 0.0 0.0" xyz="0.0 0.0 0.0"/>
      <geometry>
        <mesh filename="file:///home/hpm-mv/Documents/Building-Humanoids/Software/ros2_ws/install/reachy_description/share/reachy_description/meshes/antenna.dae"/>
      </geometry>
    </visual>
    <collision>
      <origin rpy="0.0 0 0.0" xyz="0.1 0.0 0.1"/>
      <geometry>
        <cylinder length="0.0" radius="0.0"/>
      </geometry>
    </collision>
  </link>
  <joint name="l_antenna" type="revolute">
    <origin rpy="0.166 -1.054 -1.11" xyz="-0.052 0.057 0.086"/>
    <parent link="head"/>
    <child link="l_antenna_link"/>
    <axis xyz="0 0 1"/>
    <limit effort="10." lower="-2.618" upper="2.618" velocity="0.0"/>
  </joint>
  <link name="r_antenna_link">
    <inertial>
      <origin rpy="0.0 0.0 0.0" xyz="-0.001 0.0 0.008"/>
      <mass value="0.004"/>
      <inertia ixx="1.794e-7" ixy="-1.240e-5" ixz="1.91701e-8" iyy="1.5e-7" iyz="3.169e-6" izz="1.933e-7"/>
    </inertial>
    <visual name="">
      <origin rpy="0.0 0.0 0.0" xyz="0.0 0.0 0.0"/>
      <geometry>
        <mesh filename="file:///home/hpm-mv/Documents/Building-Humanoids/Software/ros2_ws/install/reachy_description/share/reachy_description/meshes/antenna.dae"/>
      </geometry>
    </visual>
    <collision>
      <origin rpy="0.0 0.0 0.0" xyz="0.0 0.0 0.0"/>
      <geometry>
        <cylinder length="0.0" radius="0.0"/>
      </geometry>
    </collision>
  </link>
  <joint name="r_antenna" type="revolute">
    <origin rpy="-0.166 -1.054 1.11" xyz="-0.052 -0.057 0.086"/>
    <parent link="head"/>
    <child link="r_antenna_link"/>
    <axis xyz="0 0 1"/>
    <limit effort="10." lower="-2.618" upper="2.618" velocity="0.0"/>
  </joint>
  <!-- <ros2_control name="head" type="system">
    <hardware>
      <plugin>mock_components/GenericSystem</plugin>
    </hardware>
    <joint name="neck_roll">
      <state_interface name="position">
        <param name="initial_value">0.0</param>
      </state_interface>
      <state_interface name="velocity">
        <param name="initial_value">0.0</param>
      </state_interface>
      <state_interface name="effort">
        <param name="initial_value">0.0</param>
      </state_interface>
      <state_interface name="temperature">
        <param name="initial_value">0.0</param>
      </state_interface>
      <state_interface name="torque">
        <param name="initial_value">0.0</param>
      </state_interface>
      <command_interface name="position"/>
      <command_interface name="torque"/>
      <command_interface name="speed_limit"/>
      <state_interface name="speed_limit"/>
      <command_interface name="torque_limit"/>
      <state_interface name="torque_limit"/>
      <state_interface name="p_gain"/>
      <command_interface name="p_gain"/>
      <state_interface name="i_gain"/>
      <command_interface name="i_gain"/>
      <state_interface name="d_gain"/>
      <command_interface name="d_gain"/>
    </joint>
    <joint name="neck_pitch">
      <state_interface name="position">
        <param name="initial_value">0.0</param>
      </state_interface>
      <state_interface name="velocity">
        <param name="initial_value">0.0</param>
      </state_interface>
      <state_interface name="effort">
        <param name="initial_value">0.0</param>
      </state_interface>
      <state_interface name="temperature">
        <param name="initial_value">0.0</param>
      </state_interface>
      <state_interface name="torque">
        <param name="initial_value">0.0</param>
      </state_interface>
      <command_interface name="position"/>
      <command_interface name="torque"/>
      <command_interface name="speed_limit"/>
      <state_interface name="speed_limit"/>
      <command_interface name="torque_limit"/>
      <state_interface name="torque_limit"/>
      <state_interface name="p_gain"/>
      <command_interface name="p_gain"/>
      <state_interface name="i_gain"/>
      <command_interface name="i_gain"/>
      <state_interface name="d_gain"/>
      <command_interface name="d_gain"/>
    </joint>
    <joint name="neck_yaw">
      <state_interface name="position">
        <param name="initial_value">0.0</param>
      </state_interface>
      <state_interface name="velocity">
        <param name="initial_value">0.0</param>
      </state_interface>
      <state_interface name="effort">
        <param name="initial_value">0.0</param>
      </state_interface>
      <state_interface name="temperature">
        <param name="initial_value">0.0</param>
      </state_interface>
      <state_interface name="torque">
        <param name="initial_value">0.0</param>
      </state_interface>
      <command_interface name="position"/>
      <command_interface name="torque"/>
      <command_interface name="speed_limit"/>
      <state_interface name="speed_limit"/>
      <command_interface name="torque_limit"/>
      <state_interface name="torque_limit"/>
      <state_interface name="p_gain"/>
      <command_interface name="p_gain"/>
      <state_interface name="i_gain"/>
      <command_interface name="i_gain"/>
      <state_interface name="d_gain"/>
      <command_interface name="d_gain"/>
    </joint>
  </ros2_control>
  <ros2_control name="antennas" type="system">
    <hardware>
      <plugin>mock_components/GenericSystem</plugin>
    </hardware>
    <joint name="l_antenna">
      <state_interface name="position">
        <param name="initial_value">0.0</param>
      </state_interface>
      <state_interface name="velocity">
        <param name="initial_value">0.0</param>
      </state_interface>
      <state_interface name="effort">
        <param name="initial_value">0.0</param>
      </state_interface>
      <state_interface name="temperature">
        <param name="initial_value">0.0</param>
      </state_interface>
      <state_interface name="torque">
        <param name="initial_value">0.0</param>
      </state_interface>
      <command_interface name="position"/>
      <command_interface name="torque"/>
      <command_interface name="speed_limit"/>
      <state_interface name="speed_limit"/>
      <command_interface name="torque_limit"/>
      <state_interface name="torque_limit"/>
      <state_interface name="p_gain"/>
      <command_interface name="p_gain"/>
      <state_interface name="i_gain"/>
      <command_interface name="i_gain"/>
      <state_interface name="d_gain"/>
      <command_interface name="d_gain"/>
    </joint>
    <joint name="r_antenna">
      <state_interface name="position">
        <param name="initial_value">0.0</param>
      </state_interface>
      <state_interface name="velocity">
        <param name="initial_value">0.0</param>
      </state_interface>
      <state_interface name="effort">
        <param name="initial_value">0.0</param>
      </state_interface>
      <state_interface name="temperature">
        <param name="initial_value">0.0</param>
      </state_interface>
      <state_interface name="torque">
        <param name="initial_value">0.0</param>
      </state_interface>
      <command_interface name="position"/>
      <command_interface name="torque"/>
      <command_interface name="speed_limit"/>
      <state_interface name="speed_limit"/>
      <command_interface name="torque_limit"/>
      <state_interface name="torque_limit"/>
      <state_interface name="p_gain"/>
      <command_interface name="p_gain"/>
      <state_interface name="i_gain"/>
      <command_interface name="i_gain"/>
      <state_interface name="d_gain"/>
      <command_interface name="d_gain"/>
    </joint>
    <joint name="l_antenna_fan">
      <state_interface name="state">
        <param name="initial_value">0.0</param>
      </state_interface>
      <command_interface name="state"/>
    </joint>
    <joint name="r_antenna_fan">
      <state_interface name="state">
        <param name="initial_value">0.0</param>
      </state_interface>
      <command_interface name="state"/>
    </joint>
  </ros2_control> -->
</robot>
